2022-09-09 15:04:02 ERROR Retry attempt failed:
Traceback (most recent call last):
  File "D:\Anaconda\lib\site-packages\urllib3\connectionpool.py", line 700, in urlopen
    self._prepare_proxy(conn)
  File "D:\Anaconda\lib\site-packages\urllib3\connectionpool.py", line 996, in _prepare_proxy
    conn.connect()
  File "D:\Anaconda\lib\site-packages\urllib3\connection.py", line 364, in connect
    self.sock = conn = self._connect_tls_proxy(hostname, conn)
  File "D:\Anaconda\lib\site-packages\urllib3\connection.py", line 499, in _connect_tls_proxy
    socket = ssl_wrap_socket(
  File "D:\Anaconda\lib\site-packages\urllib3\util\ssl_.py", line 453, in ssl_wrap_socket
    ssl_sock = _ssl_wrap_socket_impl(sock, context, tls_in_tls)
  File "D:\Anaconda\lib\site-packages\urllib3\util\ssl_.py", line 495, in _ssl_wrap_socket_impl
    return ssl_context.wrap_socket(sock)
  File "D:\Anaconda\lib\ssl.py", line 500, in wrap_socket
    return self.sslsocket_class._create(
  File "D:\Anaconda\lib\ssl.py", line 1040, in _create
    self.do_handshake()
  File "D:\Anaconda\lib\ssl.py", line 1309, in do_handshake
    self._sslobj.do_handshake()
ssl.SSLEOFError: EOF occurred in violation of protocol (_ssl.c:1129)

During handling of the above exception, another exception occurred:

Traceback (most recent call last):
  File "D:\Anaconda\lib\site-packages\requests\adapters.py", line 440, in send
    resp = conn.urlopen(
  File "D:\Anaconda\lib\site-packages\urllib3\connectionpool.py", line 787, in urlopen
    retries = retries.increment(
  File "D:\Anaconda\lib\site-packages\urllib3\util\retry.py", line 592, in increment
    raise MaxRetryError(_pool, url, error or ResponseError(cause))
urllib3.exceptions.MaxRetryError: HTTPSConnectionPool(host='api.wandb.ai', port=443): Max retries exceeded with url: /graphql (Caused by SSLError(SSLEOFError(8, 'EOF occurred in violation of protocol (_ssl.c:1129)')))

During handling of the above exception, another exception occurred:

Traceback (most recent call last):
  File "D:\Anaconda\lib\site-packages\wandb\sdk\lib\retry.py", line 113, in __call__
    result = self._call_fn(*args, **kwargs)
  File "D:\Anaconda\lib\site-packages\wandb\sdk\internal\internal_api.py", line 204, in execute
    return self.client.execute(*args, **kwargs)  # type: ignore
  File "D:\Anaconda\lib\site-packages\wandb\vendor\gql-0.2.0\wandb_gql\client.py", line 52, in execute
    result = self._get_result(document, *args, **kwargs)
  File "D:\Anaconda\lib\site-packages\wandb\vendor\gql-0.2.0\wandb_gql\client.py", line 60, in _get_result
    return self.transport.execute(document, *args, **kwargs)
  File "D:\Anaconda\lib\site-packages\wandb\vendor\gql-0.2.0\wandb_gql\transport\requests.py", line 38, in execute
    request = requests.post(self.url, **post_args)
  File "D:\Anaconda\lib\site-packages\requests\api.py", line 117, in post
    return request('post', url, data=data, json=json, **kwargs)
  File "D:\Anaconda\lib\site-packages\requests\api.py", line 61, in request
    return session.request(method=method, url=url, **kwargs)
  File "D:\Anaconda\lib\site-packages\requests\sessions.py", line 529, in request
    resp = self.send(prep, **send_kwargs)
  File "D:\Anaconda\lib\site-packages\requests\sessions.py", line 645, in send
    r = adapter.send(request, **kwargs)
  File "D:\Anaconda\lib\site-packages\requests\adapters.py", line 517, in send
    raise SSLError(e, request=request)
requests.exceptions.SSLError: HTTPSConnectionPool(host='api.wandb.ai', port=443): Max retries exceeded with url: /graphql (Caused by SSLError(SSLEOFError(8, 'EOF occurred in violation of protocol (_ssl.c:1129)')))
2022-09-20 12:48:23 ERROR Retry attempt failed:
Traceback (most recent call last):
  File "D:\Anaconda\lib\site-packages\urllib3\connectionpool.py", line 700, in urlopen
    self._prepare_proxy(conn)
  File "D:\Anaconda\lib\site-packages\urllib3\connectionpool.py", line 996, in _prepare_proxy
    conn.connect()
  File "D:\Anaconda\lib\site-packages\urllib3\connection.py", line 364, in connect
    self.sock = conn = self._connect_tls_proxy(hostname, conn)
  File "D:\Anaconda\lib\site-packages\urllib3\connection.py", line 499, in _connect_tls_proxy
    socket = ssl_wrap_socket(
  File "D:\Anaconda\lib\site-packages\urllib3\util\ssl_.py", line 453, in ssl_wrap_socket
    ssl_sock = _ssl_wrap_socket_impl(sock, context, tls_in_tls)
  File "D:\Anaconda\lib\site-packages\urllib3\util\ssl_.py", line 495, in _ssl_wrap_socket_impl
    return ssl_context.wrap_socket(sock)
  File "D:\Anaconda\lib\ssl.py", line 500, in wrap_socket
    return self.sslsocket_class._create(
  File "D:\Anaconda\lib\ssl.py", line 1040, in _create
    self.do_handshake()
  File "D:\Anaconda\lib\ssl.py", line 1309, in do_handshake
    self._sslobj.do_handshake()
ssl.SSLEOFError: EOF occurred in violation of protocol (_ssl.c:1129)

During handling of the above exception, another exception occurred:

Traceback (most recent call last):
  File "D:\Anaconda\lib\site-packages\requests\adapters.py", line 440, in send
    resp = conn.urlopen(
  File "D:\Anaconda\lib\site-packages\urllib3\connectionpool.py", line 787, in urlopen
    retries = retries.increment(
  File "D:\Anaconda\lib\site-packages\urllib3\util\retry.py", line 592, in increment
    raise MaxRetryError(_pool, url, error or ResponseError(cause))
urllib3.exceptions.MaxRetryError: HTTPSConnectionPool(host='api.wandb.ai', port=443): Max retries exceeded with url: /graphql (Caused by SSLError(SSLEOFError(8, 'EOF occurred in violation of protocol (_ssl.c:1129)')))

During handling of the above exception, another exception occurred:

Traceback (most recent call last):
  File "D:\Anaconda\lib\site-packages\wandb\sdk\lib\retry.py", line 113, in __call__
    result = self._call_fn(*args, **kwargs)
  File "D:\Anaconda\lib\site-packages\wandb\sdk\internal\internal_api.py", line 204, in execute
    return self.client.execute(*args, **kwargs)  # type: ignore
  File "D:\Anaconda\lib\site-packages\wandb\vendor\gql-0.2.0\wandb_gql\client.py", line 52, in execute
    result = self._get_result(document, *args, **kwargs)
  File "D:\Anaconda\lib\site-packages\wandb\vendor\gql-0.2.0\wandb_gql\client.py", line 60, in _get_result
    return self.transport.execute(document, *args, **kwargs)
  File "D:\Anaconda\lib\site-packages\wandb\vendor\gql-0.2.0\wandb_gql\transport\requests.py", line 38, in execute
    request = requests.post(self.url, **post_args)
  File "D:\Anaconda\lib\site-packages\requests\api.py", line 117, in post
    return request('post', url, data=data, json=json, **kwargs)
  File "D:\Anaconda\lib\site-packages\requests\api.py", line 61, in request
    return session.request(method=method, url=url, **kwargs)
  File "D:\Anaconda\lib\site-packages\requests\sessions.py", line 529, in request
    resp = self.send(prep, **send_kwargs)
  File "D:\Anaconda\lib\site-packages\requests\sessions.py", line 645, in send
    r = adapter.send(request, **kwargs)
  File "D:\Anaconda\lib\site-packages\requests\adapters.py", line 517, in send
    raise SSLError(e, request=request)
requests.exceptions.SSLError: HTTPSConnectionPool(host='api.wandb.ai', port=443): Max retries exceeded with url: /graphql (Caused by SSLError(SSLEOFError(8, 'EOF occurred in violation of protocol (_ssl.c:1129)')))
2022-09-20 12:48:54 ERROR Retry attempt failed:
Traceback (most recent call last):
  File "D:\Anaconda\lib\site-packages\urllib3\connectionpool.py", line 700, in urlopen
    self._prepare_proxy(conn)
  File "D:\Anaconda\lib\site-packages\urllib3\connectionpool.py", line 996, in _prepare_proxy
    conn.connect()
  File "D:\Anaconda\lib\site-packages\urllib3\connection.py", line 364, in connect
    self.sock = conn = self._connect_tls_proxy(hostname, conn)
  File "D:\Anaconda\lib\site-packages\urllib3\connection.py", line 499, in _connect_tls_proxy
    socket = ssl_wrap_socket(
  File "D:\Anaconda\lib\site-packages\urllib3\util\ssl_.py", line 453, in ssl_wrap_socket
    ssl_sock = _ssl_wrap_socket_impl(sock, context, tls_in_tls)
  File "D:\Anaconda\lib\site-packages\urllib3\util\ssl_.py", line 495, in _ssl_wrap_socket_impl
    return ssl_context.wrap_socket(sock)
  File "D:\Anaconda\lib\ssl.py", line 500, in wrap_socket
    return self.sslsocket_class._create(
  File "D:\Anaconda\lib\ssl.py", line 1040, in _create
    self.do_handshake()
  File "D:\Anaconda\lib\ssl.py", line 1309, in do_handshake
    self._sslobj.do_handshake()
ssl.SSLEOFError: EOF occurred in violation of protocol (_ssl.c:1129)

During handling of the above exception, another exception occurred:

Traceback (most recent call last):
  File "D:\Anaconda\lib\site-packages\requests\adapters.py", line 440, in send
    resp = conn.urlopen(
  File "D:\Anaconda\lib\site-packages\urllib3\connectionpool.py", line 787, in urlopen
    retries = retries.increment(
  File "D:\Anaconda\lib\site-packages\urllib3\util\retry.py", line 592, in increment
    raise MaxRetryError(_pool, url, error or ResponseError(cause))
urllib3.exceptions.MaxRetryError: HTTPSConnectionPool(host='api.wandb.ai', port=443): Max retries exceeded with url: /graphql (Caused by SSLError(SSLEOFError(8, 'EOF occurred in violation of protocol (_ssl.c:1129)')))

During handling of the above exception, another exception occurred:

Traceback (most recent call last):
  File "D:\Anaconda\lib\site-packages\wandb\sdk\lib\retry.py", line 113, in __call__
    result = self._call_fn(*args, **kwargs)
  File "D:\Anaconda\lib\site-packages\wandb\sdk\internal\internal_api.py", line 204, in execute
    return self.client.execute(*args, **kwargs)  # type: ignore
  File "D:\Anaconda\lib\site-packages\wandb\vendor\gql-0.2.0\wandb_gql\client.py", line 52, in execute
    result = self._get_result(document, *args, **kwargs)
  File "D:\Anaconda\lib\site-packages\wandb\vendor\gql-0.2.0\wandb_gql\client.py", line 60, in _get_result
    return self.transport.execute(document, *args, **kwargs)
  File "D:\Anaconda\lib\site-packages\wandb\vendor\gql-0.2.0\wandb_gql\transport\requests.py", line 38, in execute
    request = requests.post(self.url, **post_args)
  File "D:\Anaconda\lib\site-packages\requests\api.py", line 117, in post
    return request('post', url, data=data, json=json, **kwargs)
  File "D:\Anaconda\lib\site-packages\requests\api.py", line 61, in request
    return session.request(method=method, url=url, **kwargs)
  File "D:\Anaconda\lib\site-packages\requests\sessions.py", line 529, in request
    resp = self.send(prep, **send_kwargs)
  File "D:\Anaconda\lib\site-packages\requests\sessions.py", line 645, in send
    r = adapter.send(request, **kwargs)
  File "D:\Anaconda\lib\site-packages\requests\adapters.py", line 517, in send
    raise SSLError(e, request=request)
requests.exceptions.SSLError: HTTPSConnectionPool(host='api.wandb.ai', port=443): Max retries exceeded with url: /graphql (Caused by SSLError(SSLEOFError(8, 'EOF occurred in violation of protocol (_ssl.c:1129)')))
